2018-11-08 17:23:53,443 ERROR: Exception on / [GET] [in D:\Anaconda3\envs\test_py3\lib\site-packages\flask\app.py:1761]
Traceback (most recent call last):
  File "D:\Anaconda3\envs\test_py3\lib\site-packages\flask\app.py", line 2292, in wsgi_app
    response = self.full_dispatch_request()
  File "D:\Anaconda3\envs\test_py3\lib\site-packages\flask\app.py", line 1815, in full_dispatch_request
    rv = self.handle_user_exception(e)
  File "D:\Anaconda3\envs\test_py3\lib\site-packages\flask\app.py", line 1718, in handle_user_exception
    reraise(exc_type, exc_value, tb)
  File "D:\Anaconda3\envs\test_py3\lib\site-packages\flask\_compat.py", line 35, in reraise
    raise value
  File "D:\Anaconda3\envs\test_py3\lib\site-packages\flask\app.py", line 1813, in full_dispatch_request
    rv = self.dispatch_request()
  File "D:\Anaconda3\envs\test_py3\lib\site-packages\flask\app.py", line 1799, in dispatch_request
    return self.view_functions[rule.endpoint](**req.view_args)
  File "E:\github\mycode\recruitment\app\main\views.py", line 16, in index
    return render_template('main/index.html', title="首页")
  File "D:\Anaconda3\envs\test_py3\lib\site-packages\flask\templating.py", line 133, in render_template
    ctx.app.update_template_context(context)
  File "D:\Anaconda3\envs\test_py3\lib\site-packages\flask\app.py", line 792, in update_template_context
    context.update(func())
  File "D:\Anaconda3\envs\test_py3\lib\site-packages\flask_login\utils.py", line 368, in _user_context_processor
    return dict(current_user=_get_user())
  File "D:\Anaconda3\envs\test_py3\lib\site-packages\flask_login\utils.py", line 335, in _get_user
    current_app.login_manager._load_user()
  File "D:\Anaconda3\envs\test_py3\lib\site-packages\flask_login\login_manager.py", line 359, in _load_user
    return self.reload_user()
  File "D:\Anaconda3\envs\test_py3\lib\site-packages\flask_login\login_manager.py", line 317, in reload_user
    "No user_loader has been installed for this "
Exception: No user_loader has been installed for this LoginManager. Refer tohttps://flask-login.readthedocs.io/en/latest/#how-it-works for more info.
2018-11-08 17:23:57,271 ERROR: Exception on / [GET] [in D:\Anaconda3\envs\test_py3\lib\site-packages\flask\app.py:1761]
Traceback (most recent call last):
  File "D:\Anaconda3\envs\test_py3\lib\site-packages\flask\app.py", line 2292, in wsgi_app
    response = self.full_dispatch_request()
  File "D:\Anaconda3\envs\test_py3\lib\site-packages\flask\app.py", line 1815, in full_dispatch_request
    rv = self.handle_user_exception(e)
  File "D:\Anaconda3\envs\test_py3\lib\site-packages\flask\app.py", line 1718, in handle_user_exception
    reraise(exc_type, exc_value, tb)
  File "D:\Anaconda3\envs\test_py3\lib\site-packages\flask\_compat.py", line 35, in reraise
    raise value
  File "D:\Anaconda3\envs\test_py3\lib\site-packages\flask\app.py", line 1813, in full_dispatch_request
    rv = self.dispatch_request()
  File "D:\Anaconda3\envs\test_py3\lib\site-packages\flask\app.py", line 1799, in dispatch_request
    return self.view_functions[rule.endpoint](**req.view_args)
  File "E:\github\mycode\recruitment\app\main\views.py", line 16, in index
    return render_template('main/index.html', title="首页")
  File "D:\Anaconda3\envs\test_py3\lib\site-packages\flask\templating.py", line 133, in render_template
    ctx.app.update_template_context(context)
  File "D:\Anaconda3\envs\test_py3\lib\site-packages\flask\app.py", line 792, in update_template_context
    context.update(func())
  File "D:\Anaconda3\envs\test_py3\lib\site-packages\flask_login\utils.py", line 368, in _user_context_processor
    return dict(current_user=_get_user())
  File "D:\Anaconda3\envs\test_py3\lib\site-packages\flask_login\utils.py", line 335, in _get_user
    current_app.login_manager._load_user()
  File "D:\Anaconda3\envs\test_py3\lib\site-packages\flask_login\login_manager.py", line 359, in _load_user
    return self.reload_user()
  File "D:\Anaconda3\envs\test_py3\lib\site-packages\flask_login\login_manager.py", line 317, in reload_user
    "No user_loader has been installed for this "
Exception: No user_loader has been installed for this LoginManager. Refer tohttps://flask-login.readthedocs.io/en/latest/#how-it-works for more info.
2018-11-08 17:24:26,478 ERROR: Exception on /aaa [GET] [in D:\Anaconda3\envs\test_py3\lib\site-packages\flask\app.py:1761]
Traceback (most recent call last):
  File "D:\Anaconda3\envs\test_py3\lib\site-packages\flask\app.py", line 1813, in full_dispatch_request
    rv = self.dispatch_request()
  File "D:\Anaconda3\envs\test_py3\lib\site-packages\flask\app.py", line 1791, in dispatch_request
    self.raise_routing_exception(req)
  File "D:\Anaconda3\envs\test_py3\lib\site-packages\flask\app.py", line 1774, in raise_routing_exception
    raise request.routing_exception
  File "D:\Anaconda3\envs\test_py3\lib\site-packages\flask\ctx.py", line 336, in match_request
    self.url_adapter.match(return_rule=True)
  File "D:\Anaconda3\envs\test_py3\lib\site-packages\werkzeug\routing.py", line 1581, in match
    raise NotFound()
werkzeug.exceptions.NotFound: 404 Not Found: The requested URL was not found on the server.  If you entered the URL manually please check your spelling and try again.

During handling of the above exception, another exception occurred:

Traceback (most recent call last):
  File "D:\Anaconda3\envs\test_py3\lib\site-packages\flask\app.py", line 2292, in wsgi_app
    response = self.full_dispatch_request()
  File "D:\Anaconda3\envs\test_py3\lib\site-packages\flask\app.py", line 1815, in full_dispatch_request
    rv = self.handle_user_exception(e)
  File "D:\Anaconda3\envs\test_py3\lib\site-packages\flask\app.py", line 1713, in handle_user_exception
    return self.handle_http_exception(e)
  File "D:\Anaconda3\envs\test_py3\lib\site-packages\flask\app.py", line 1644, in handle_http_exception
    return handler(e)
  File "E:\github\mycode\recruitment\app\errors\handlers.py", line 15, in not_found_error
    return render_template('errors/404.html'), 404
  File "D:\Anaconda3\envs\test_py3\lib\site-packages\flask\templating.py", line 133, in render_template
    ctx.app.update_template_context(context)
  File "D:\Anaconda3\envs\test_py3\lib\site-packages\flask\app.py", line 792, in update_template_context
    context.update(func())
  File "D:\Anaconda3\envs\test_py3\lib\site-packages\flask_login\utils.py", line 368, in _user_context_processor
    return dict(current_user=_get_user())
  File "D:\Anaconda3\envs\test_py3\lib\site-packages\flask_login\utils.py", line 335, in _get_user
    current_app.login_manager._load_user()
  File "D:\Anaconda3\envs\test_py3\lib\site-packages\flask_login\login_manager.py", line 359, in _load_user
    return self.reload_user()
  File "D:\Anaconda3\envs\test_py3\lib\site-packages\flask_login\login_manager.py", line 317, in reload_user
    "No user_loader has been installed for this "
Exception: No user_loader has been installed for this LoginManager. Refer tohttps://flask-login.readthedocs.io/en/latest/#how-it-works for more info.
2018-11-08 17:25:03,740 INFO: 公司后台 startup [in E:\github\mycode\recruitment\app\__init__.py:85]
2018-11-08 17:25:19,556 ERROR: Exception on /index [GET] [in D:\Anaconda3\envs\test_py3\lib\site-packages\flask\app.py:1761]
Traceback (most recent call last):
  File "D:\Anaconda3\envs\test_py3\lib\site-packages\flask\app.py", line 2292, in wsgi_app
    response = self.full_dispatch_request()
  File "D:\Anaconda3\envs\test_py3\lib\site-packages\flask\app.py", line 1815, in full_dispatch_request
    rv = self.handle_user_exception(e)
  File "D:\Anaconda3\envs\test_py3\lib\site-packages\flask\app.py", line 1718, in handle_user_exception
    reraise(exc_type, exc_value, tb)
  File "D:\Anaconda3\envs\test_py3\lib\site-packages\flask\_compat.py", line 35, in reraise
    raise value
  File "D:\Anaconda3\envs\test_py3\lib\site-packages\flask\app.py", line 1813, in full_dispatch_request
    rv = self.dispatch_request()
  File "D:\Anaconda3\envs\test_py3\lib\site-packages\flask\app.py", line 1799, in dispatch_request
    return self.view_functions[rule.endpoint](**req.view_args)
  File "E:\github\mycode\recruitment\app\main\views.py", line 16, in index
    return render_template('main/index.html', title="首页")
  File "D:\Anaconda3\envs\test_py3\lib\site-packages\flask\templating.py", line 133, in render_template
    ctx.app.update_template_context(context)
  File "D:\Anaconda3\envs\test_py3\lib\site-packages\flask\app.py", line 792, in update_template_context
    context.update(func())
  File "D:\Anaconda3\envs\test_py3\lib\site-packages\flask_login\utils.py", line 368, in _user_context_processor
    return dict(current_user=_get_user())
  File "D:\Anaconda3\envs\test_py3\lib\site-packages\flask_login\utils.py", line 335, in _get_user
    current_app.login_manager._load_user()
  File "D:\Anaconda3\envs\test_py3\lib\site-packages\flask_login\login_manager.py", line 359, in _load_user
    return self.reload_user()
  File "D:\Anaconda3\envs\test_py3\lib\site-packages\flask_login\login_manager.py", line 317, in reload_user
    "No user_loader has been installed for this "
Exception: No user_loader has been installed for this LoginManager. Refer tohttps://flask-login.readthedocs.io/en/latest/#how-it-works for more info.
2018-11-08 17:27:34,065 INFO: 公司后台 startup [in E:\github\mycode\recruitment\app\__init__.py:85]
