2018-11-11 00:12:43,541 ERROR: Exception on /user/index/ [GET] [in D:\Develop\Anaconda\envs\py37\lib\site-packages\flask\app.py:1761]
Traceback (most recent call last):
  File "D:\Develop\Anaconda\envs\py37\lib\site-packages\flask\app.py", line 2292, in wsgi_app
    response = self.full_dispatch_request()
  File "D:\Develop\Anaconda\envs\py37\lib\site-packages\flask\app.py", line 1815, in full_dispatch_request
    rv = self.handle_user_exception(e)
  File "D:\Develop\Anaconda\envs\py37\lib\site-packages\flask\app.py", line 1718, in handle_user_exception
    reraise(exc_type, exc_value, tb)
  File "D:\Develop\Anaconda\envs\py37\lib\site-packages\flask\_compat.py", line 35, in reraise
    raise value
  File "D:\Develop\Anaconda\envs\py37\lib\site-packages\flask\app.py", line 1813, in full_dispatch_request
    rv = self.dispatch_request()
  File "D:\Develop\Anaconda\envs\py37\lib\site-packages\flask\app.py", line 1799, in dispatch_request
    return self.view_functions[rule.endpoint](**req.view_args)
  File "D:\Develop\Anaconda\envs\py37\lib\site-packages\flask_login\utils.py", line 261, in decorated_view
    return func(*args, **kwargs)
  File "E:\GitHub\mycode\recruitment\app\main\user\views.py", line 36, in user_index
    form=searchform, q=query)
  File "D:\Develop\Anaconda\envs\py37\lib\site-packages\flask\templating.py", line 135, in render_template
    context, ctx.app)
  File "D:\Develop\Anaconda\envs\py37\lib\site-packages\flask\templating.py", line 117, in _render
    rv = template.render(context)
  File "D:\Develop\Anaconda\envs\py37\lib\site-packages\jinja2\asyncsupport.py", line 76, in render
    return original_render(self, *args, **kwargs)
  File "D:\Develop\Anaconda\envs\py37\lib\site-packages\jinja2\environment.py", line 1008, in render
    return self.environment.handle_exception(exc_info, True)
  File "D:\Develop\Anaconda\envs\py37\lib\site-packages\jinja2\environment.py", line 780, in handle_exception
    reraise(exc_type, exc_value, tb)
  File "D:\Develop\Anaconda\envs\py37\lib\site-packages\jinja2\_compat.py", line 37, in reraise
    raise value.with_traceback(tb)
  File "E:\GitHub\mycode\recruitment\app\templates\main\user\index.html", line 2, in top-level template code
    {% import "_macros.html" as macros %}
  File "E:\GitHub\mycode\recruitment\app\templates\base.html", line 1, in top-level template code
    {% extends 'bootstrap/base.html' %}
  File "D:\Develop\Anaconda\envs\py37\lib\site-packages\flask_bootstrap\templates\bootstrap\base.html", line 1, in top-level template code
    {% block doc -%}
  File "D:\Develop\Anaconda\envs\py37\lib\site-packages\flask_bootstrap\templates\bootstrap\base.html", line 4, in block "doc"
    {%- block html %}
  File "D:\Develop\Anaconda\envs\py37\lib\site-packages\flask_bootstrap\templates\bootstrap\base.html", line 20, in block "html"
    {% block body -%}
  File "D:\Develop\Anaconda\envs\py37\lib\site-packages\flask_bootstrap\templates\bootstrap\base.html", line 23, in block "body"
    {% block content -%}
  File "E:\GitHub\mycode\recruitment\app\templates\base.html", line 73, in block "content"
    {% block app_content %}{% endblock %}
  File "E:\GitHub\mycode\recruitment\app\templates\main\user\index.html", line 90, in block "app_content"
    {{ macros.pagination_widget(pagination, '.user_index', q) }}
  File "D:\Develop\Anaconda\envs\py37\lib\site-packages\jinja2\runtime.py", line 579, in _invoke
    rv = self._func(*arguments)
  File "E:\GitHub\mycode\recruitment\app\templates\_macros.html", line 12, in template
    <a href="{{ url_for(endpoint, page = p, **kwargs) }}{{ fragment }}">{{ p }}</a>
  File "D:\Develop\Anaconda\envs\py37\lib\site-packages\flask\helpers.py", line 356, in url_for
    return appctx.app.handle_url_build_error(error, endpoint, values)
  File "D:\Develop\Anaconda\envs\py37\lib\site-packages\flask\app.py", line 2061, in handle_url_build_error
    reraise(exc_type, exc_value, tb)
  File "D:\Develop\Anaconda\envs\py37\lib\site-packages\flask\_compat.py", line 35, in reraise
    raise value
  File "D:\Develop\Anaconda\envs\py37\lib\site-packages\flask\helpers.py", line 345, in url_for
    force_external=external)
  File "D:\Develop\Anaconda\envs\py37\lib\site-packages\werkzeug\routing.py", line 1776, in build
    raise BuildError(endpoint, values, method, self)
werkzeug.routing.BuildError: Could not build url for endpoint '' with values ['page']. Did you mean 'auth.reset_password_request' instead?
2018-11-11 00:14:49,586 INFO: 公司后台 startup [in E:\GitHub\mycode\recruitment\app\__init__.py:85]
2018-11-11 00:15:05,680 INFO: 公司后台 startup [in E:\GitHub\mycode\recruitment\app\__init__.py:85]
2018-11-11 00:15:31,131 INFO: 公司后台 startup [in E:\GitHub\mycode\recruitment\app\__init__.py:85]
2018-11-11 00:16:40,334 INFO: 公司后台 startup [in E:\GitHub\mycode\recruitment\app\__init__.py:85]
2018-11-11 00:16:45,278 ERROR: Exception on /user/index/ [GET] [in D:\Develop\Anaconda\envs\py37\lib\site-packages\flask\app.py:1761]
Traceback (most recent call last):
  File "D:\Develop\Anaconda\envs\py37\lib\site-packages\flask\app.py", line 2292, in wsgi_app
    response = self.full_dispatch_request()
  File "D:\Develop\Anaconda\envs\py37\lib\site-packages\flask\app.py", line 1815, in full_dispatch_request
    rv = self.handle_user_exception(e)
  File "D:\Develop\Anaconda\envs\py37\lib\site-packages\flask\app.py", line 1718, in handle_user_exception
    reraise(exc_type, exc_value, tb)
  File "D:\Develop\Anaconda\envs\py37\lib\site-packages\flask\_compat.py", line 35, in reraise
    raise value
  File "D:\Develop\Anaconda\envs\py37\lib\site-packages\flask\app.py", line 1813, in full_dispatch_request
    rv = self.dispatch_request()
  File "D:\Develop\Anaconda\envs\py37\lib\site-packages\flask\app.py", line 1799, in dispatch_request
    return self.view_functions[rule.endpoint](**req.view_args)
  File "D:\Develop\Anaconda\envs\py37\lib\site-packages\flask_login\utils.py", line 261, in decorated_view
    return func(*args, **kwargs)
  File "E:\GitHub\mycode\recruitment\app\main\user\views.py", line 35, in user_index
    title='用户列表', next_url=next_url, prev_url=prev_url, page=page,
NameError: name 'next_url' is not defined
2018-11-11 00:17:03,939 INFO: 公司后台 startup [in E:\GitHub\mycode\recruitment\app\__init__.py:85]
2018-11-11 00:17:08,288 ERROR: Exception on /user/index/ [GET] [in D:\Develop\Anaconda\envs\py37\lib\site-packages\flask\app.py:1761]
Traceback (most recent call last):
  File "D:\Develop\Anaconda\envs\py37\lib\site-packages\flask\app.py", line 2292, in wsgi_app
    response = self.full_dispatch_request()
  File "D:\Develop\Anaconda\envs\py37\lib\site-packages\flask\app.py", line 1815, in full_dispatch_request
    rv = self.handle_user_exception(e)
  File "D:\Develop\Anaconda\envs\py37\lib\site-packages\flask\app.py", line 1718, in handle_user_exception
    reraise(exc_type, exc_value, tb)
  File "D:\Develop\Anaconda\envs\py37\lib\site-packages\flask\_compat.py", line 35, in reraise
    raise value
  File "D:\Develop\Anaconda\envs\py37\lib\site-packages\flask\app.py", line 1813, in full_dispatch_request
    rv = self.dispatch_request()
  File "D:\Develop\Anaconda\envs\py37\lib\site-packages\flask\app.py", line 1799, in dispatch_request
    return self.view_functions[rule.endpoint](**req.view_args)
  File "D:\Develop\Anaconda\envs\py37\lib\site-packages\flask_login\utils.py", line 261, in decorated_view
    return func(*args, **kwargs)
  File "E:\GitHub\mycode\recruitment\app\main\user\views.py", line 35, in user_index
    title='用户列表', next_url=next_url, prev_url=prev_url, page=page,
NameError: name 'next_url' is not defined
2018-11-11 00:17:35,049 INFO: 公司后台 startup [in E:\GitHub\mycode\recruitment\app\__init__.py:85]
2018-11-11 00:18:32,622 INFO: 公司后台 startup [in E:\GitHub\mycode\recruitment\app\__init__.py:85]
2018-11-11 00:19:32,045 INFO: 公司后台 startup [in E:\GitHub\mycode\recruitment\app\__init__.py:85]
2018-11-11 00:20:25,340 INFO: 公司后台 startup [in E:\GitHub\mycode\recruitment\app\__init__.py:85]
2018-11-11 00:21:54,890 INFO: 公司后台 startup [in E:\GitHub\mycode\recruitment\app\__init__.py:85]
2018-11-11 00:21:59,039 ERROR: Exception on /user/index/ [GET] [in D:\Develop\Anaconda\envs\py37\lib\site-packages\flask\app.py:1761]
Traceback (most recent call last):
  File "D:\Develop\Anaconda\envs\py37\lib\site-packages\flask\app.py", line 2292, in wsgi_app
    response = self.full_dispatch_request()
  File "D:\Develop\Anaconda\envs\py37\lib\site-packages\flask\app.py", line 1815, in full_dispatch_request
    rv = self.handle_user_exception(e)
  File "D:\Develop\Anaconda\envs\py37\lib\site-packages\flask\app.py", line 1718, in handle_user_exception
    reraise(exc_type, exc_value, tb)
  File "D:\Develop\Anaconda\envs\py37\lib\site-packages\flask\_compat.py", line 35, in reraise
    raise value
  File "D:\Develop\Anaconda\envs\py37\lib\site-packages\flask\app.py", line 1813, in full_dispatch_request
    rv = self.dispatch_request()
  File "D:\Develop\Anaconda\envs\py37\lib\site-packages\flask\app.py", line 1799, in dispatch_request
    return self.view_functions[rule.endpoint](**req.view_args)
  File "D:\Develop\Anaconda\envs\py37\lib\site-packages\flask_login\utils.py", line 261, in decorated_view
    return func(*args, **kwargs)
  File "E:\GitHub\mycode\recruitment\app\main\user\views.py", line 23, in user_index
    query = request.args.get('q', '').trim()
AttributeError: 'str' object has no attribute 'trim'
2018-11-11 00:22:40,133 INFO: 公司后台 startup [in E:\GitHub\mycode\recruitment\app\__init__.py:85]
2018-11-11 00:24:29,884 INFO: 公司后台 startup [in E:\GitHub\mycode\recruitment\app\__init__.py:85]
2018-11-11 00:25:01,238 INFO: 公司后台 startup [in E:\GitHub\mycode\recruitment\app\__init__.py:85]
2018-11-11 00:25:34,613 INFO: 公司后台 startup [in E:\GitHub\mycode\recruitment\app\__init__.py:85]
2018-11-12 20:28:59,938 INFO: 公司后台 startup [in E:\GitHub\mycode\recruitment\app\__init__.py:85]
2018-11-12 20:39:07,228 INFO: 公司后台 startup [in E:\GitHub\mycode\recruitment\app\__init__.py:85]
