2018-11-08 17:27:37,712 ERROR: Exception on /auth/login [GET] [in D:\Anaconda3\envs\test_py3\lib\site-packages\flask\app.py:1761]
Traceback (most recent call last):
  File "D:\Anaconda3\envs\test_py3\lib\site-packages\flask\app.py", line 2292, in wsgi_app
    response = self.full_dispatch_request()
  File "D:\Anaconda3\envs\test_py3\lib\site-packages\flask\app.py", line 1815, in full_dispatch_request
    rv = self.handle_user_exception(e)
  File "D:\Anaconda3\envs\test_py3\lib\site-packages\flask\app.py", line 1718, in handle_user_exception
    reraise(exc_type, exc_value, tb)
  File "D:\Anaconda3\envs\test_py3\lib\site-packages\flask\_compat.py", line 35, in reraise
    raise value
  File "D:\Anaconda3\envs\test_py3\lib\site-packages\flask\app.py", line 1811, in full_dispatch_request
    rv = self.preprocess_request()
  File "D:\Anaconda3\envs\test_py3\lib\site-packages\flask\app.py", line 2087, in preprocess_request
    rv = func()
  File "E:\github\mycode\recruitment\app\main\views.py", line 16, in before_request
    if current_user.is_authenticated:
  File "D:\Anaconda3\envs\test_py3\lib\site-packages\werkzeug\local.py", line 347, in __getattr__
    return getattr(self._get_current_object(), name)
  File "D:\Anaconda3\envs\test_py3\lib\site-packages\werkzeug\local.py", line 306, in _get_current_object
    return self.__local()
  File "D:\Anaconda3\envs\test_py3\lib\site-packages\flask_login\utils.py", line 26, in <lambda>
    current_user = LocalProxy(lambda: _get_user())
  File "D:\Anaconda3\envs\test_py3\lib\site-packages\flask_login\utils.py", line 335, in _get_user
    current_app.login_manager._load_user()
  File "D:\Anaconda3\envs\test_py3\lib\site-packages\flask_login\login_manager.py", line 359, in _load_user
    return self.reload_user()
  File "D:\Anaconda3\envs\test_py3\lib\site-packages\flask_login\login_manager.py", line 317, in reload_user
    "No user_loader has been installed for this "
Exception: No user_loader has been installed for this LoginManager. Refer tohttps://flask-login.readthedocs.io/en/latest/#how-it-works for more info.
2018-11-08 17:27:39,939 ERROR: Exception on / [GET] [in D:\Anaconda3\envs\test_py3\lib\site-packages\flask\app.py:1761]
Traceback (most recent call last):
  File "D:\Anaconda3\envs\test_py3\lib\site-packages\flask\app.py", line 2292, in wsgi_app
    response = self.full_dispatch_request()
  File "D:\Anaconda3\envs\test_py3\lib\site-packages\flask\app.py", line 1815, in full_dispatch_request
    rv = self.handle_user_exception(e)
  File "D:\Anaconda3\envs\test_py3\lib\site-packages\flask\app.py", line 1718, in handle_user_exception
    reraise(exc_type, exc_value, tb)
  File "D:\Anaconda3\envs\test_py3\lib\site-packages\flask\_compat.py", line 35, in reraise
    raise value
  File "D:\Anaconda3\envs\test_py3\lib\site-packages\flask\app.py", line 1811, in full_dispatch_request
    rv = self.preprocess_request()
  File "D:\Anaconda3\envs\test_py3\lib\site-packages\flask\app.py", line 2087, in preprocess_request
    rv = func()
  File "E:\github\mycode\recruitment\app\main\views.py", line 16, in before_request
    if current_user.is_authenticated:
  File "D:\Anaconda3\envs\test_py3\lib\site-packages\werkzeug\local.py", line 347, in __getattr__
    return getattr(self._get_current_object(), name)
  File "D:\Anaconda3\envs\test_py3\lib\site-packages\werkzeug\local.py", line 306, in _get_current_object
    return self.__local()
  File "D:\Anaconda3\envs\test_py3\lib\site-packages\flask_login\utils.py", line 26, in <lambda>
    current_user = LocalProxy(lambda: _get_user())
  File "D:\Anaconda3\envs\test_py3\lib\site-packages\flask_login\utils.py", line 335, in _get_user
    current_app.login_manager._load_user()
  File "D:\Anaconda3\envs\test_py3\lib\site-packages\flask_login\login_manager.py", line 359, in _load_user
    return self.reload_user()
  File "D:\Anaconda3\envs\test_py3\lib\site-packages\flask_login\login_manager.py", line 317, in reload_user
    "No user_loader has been installed for this "
Exception: No user_loader has been installed for this LoginManager. Refer tohttps://flask-login.readthedocs.io/en/latest/#how-it-works for more info.
2018-11-08 17:27:42,451 ERROR: Exception on /auth/login [GET] [in D:\Anaconda3\envs\test_py3\lib\site-packages\flask\app.py:1761]
Traceback (most recent call last):
  File "D:\Anaconda3\envs\test_py3\lib\site-packages\flask\app.py", line 2292, in wsgi_app
    response = self.full_dispatch_request()
  File "D:\Anaconda3\envs\test_py3\lib\site-packages\flask\app.py", line 1815, in full_dispatch_request
    rv = self.handle_user_exception(e)
  File "D:\Anaconda3\envs\test_py3\lib\site-packages\flask\app.py", line 1718, in handle_user_exception
    reraise(exc_type, exc_value, tb)
  File "D:\Anaconda3\envs\test_py3\lib\site-packages\flask\_compat.py", line 35, in reraise
    raise value
  File "D:\Anaconda3\envs\test_py3\lib\site-packages\flask\app.py", line 1811, in full_dispatch_request
    rv = self.preprocess_request()
  File "D:\Anaconda3\envs\test_py3\lib\site-packages\flask\app.py", line 2087, in preprocess_request
    rv = func()
  File "E:\github\mycode\recruitment\app\main\views.py", line 16, in before_request
    if current_user.is_authenticated:
  File "D:\Anaconda3\envs\test_py3\lib\site-packages\werkzeug\local.py", line 347, in __getattr__
    return getattr(self._get_current_object(), name)
  File "D:\Anaconda3\envs\test_py3\lib\site-packages\werkzeug\local.py", line 306, in _get_current_object
    return self.__local()
  File "D:\Anaconda3\envs\test_py3\lib\site-packages\flask_login\utils.py", line 26, in <lambda>
    current_user = LocalProxy(lambda: _get_user())
  File "D:\Anaconda3\envs\test_py3\lib\site-packages\flask_login\utils.py", line 335, in _get_user
    current_app.login_manager._load_user()
  File "D:\Anaconda3\envs\test_py3\lib\site-packages\flask_login\login_manager.py", line 359, in _load_user
    return self.reload_user()
  File "D:\Anaconda3\envs\test_py3\lib\site-packages\flask_login\login_manager.py", line 317, in reload_user
    "No user_loader has been installed for this "
Exception: No user_loader has been installed for this LoginManager. Refer tohttps://flask-login.readthedocs.io/en/latest/#how-it-works for more info.
2018-11-08 17:27:45,643 ERROR: Exception on / [GET] [in D:\Anaconda3\envs\test_py3\lib\site-packages\flask\app.py:1761]
Traceback (most recent call last):
  File "D:\Anaconda3\envs\test_py3\lib\site-packages\flask\app.py", line 2292, in wsgi_app
    response = self.full_dispatch_request()
  File "D:\Anaconda3\envs\test_py3\lib\site-packages\flask\app.py", line 1815, in full_dispatch_request
    rv = self.handle_user_exception(e)
  File "D:\Anaconda3\envs\test_py3\lib\site-packages\flask\app.py", line 1718, in handle_user_exception
    reraise(exc_type, exc_value, tb)
  File "D:\Anaconda3\envs\test_py3\lib\site-packages\flask\_compat.py", line 35, in reraise
    raise value
  File "D:\Anaconda3\envs\test_py3\lib\site-packages\flask\app.py", line 1811, in full_dispatch_request
    rv = self.preprocess_request()
  File "D:\Anaconda3\envs\test_py3\lib\site-packages\flask\app.py", line 2087, in preprocess_request
    rv = func()
  File "E:\github\mycode\recruitment\app\main\views.py", line 16, in before_request
    if current_user.is_authenticated:
  File "D:\Anaconda3\envs\test_py3\lib\site-packages\werkzeug\local.py", line 347, in __getattr__
    return getattr(self._get_current_object(), name)
  File "D:\Anaconda3\envs\test_py3\lib\site-packages\werkzeug\local.py", line 306, in _get_current_object
    return self.__local()
  File "D:\Anaconda3\envs\test_py3\lib\site-packages\flask_login\utils.py", line 26, in <lambda>
    current_user = LocalProxy(lambda: _get_user())
  File "D:\Anaconda3\envs\test_py3\lib\site-packages\flask_login\utils.py", line 335, in _get_user
    current_app.login_manager._load_user()
  File "D:\Anaconda3\envs\test_py3\lib\site-packages\flask_login\login_manager.py", line 359, in _load_user
    return self.reload_user()
  File "D:\Anaconda3\envs\test_py3\lib\site-packages\flask_login\login_manager.py", line 317, in reload_user
    "No user_loader has been installed for this "
Exception: No user_loader has been installed for this LoginManager. Refer tohttps://flask-login.readthedocs.io/en/latest/#how-it-works for more info.
2018-11-08 17:29:32,168 INFO: 公司后台 startup [in E:\github\mycode\recruitment\app\__init__.py:85]
2018-11-08 17:29:35,709 ERROR: Exception on / [GET] [in D:\Anaconda3\envs\test_py3\lib\site-packages\flask\app.py:1761]
Traceback (most recent call last):
  File "D:\Anaconda3\envs\test_py3\lib\site-packages\flask\app.py", line 2292, in wsgi_app
    response = self.full_dispatch_request()
  File "D:\Anaconda3\envs\test_py3\lib\site-packages\flask\app.py", line 1815, in full_dispatch_request
    rv = self.handle_user_exception(e)
  File "D:\Anaconda3\envs\test_py3\lib\site-packages\flask\app.py", line 1718, in handle_user_exception
    reraise(exc_type, exc_value, tb)
  File "D:\Anaconda3\envs\test_py3\lib\site-packages\flask\_compat.py", line 35, in reraise
    raise value
  File "D:\Anaconda3\envs\test_py3\lib\site-packages\flask\app.py", line 1811, in full_dispatch_request
    rv = self.preprocess_request()
  File "D:\Anaconda3\envs\test_py3\lib\site-packages\flask\app.py", line 2087, in preprocess_request
    rv = func()
  File "E:\github\mycode\recruitment\app\main\views.py", line 20, in before_request
    g.locale = str(get_locale())
  File "D:\Anaconda3\envs\test_py3\lib\site-packages\flask_babel\__init__.py", line 253, in get_locale
    babel = current_app.extensions['babel']
KeyError: 'babel'
2018-11-08 17:31:47,745 INFO: 公司后台 startup [in E:\github\mycode\recruitment\app\__init__.py:85]
