2018-11-07 16:03:13,322 ERROR: Exception on /user/add [GET] [in D:\Anaconda3\envs\test_py3\lib\site-packages\flask\app.py:1761]
Traceback (most recent call last):
  File "D:\Anaconda3\envs\test_py3\lib\site-packages\flask\app.py", line 2292, in wsgi_app
    response = self.full_dispatch_request()
  File "D:\Anaconda3\envs\test_py3\lib\site-packages\flask\app.py", line 1815, in full_dispatch_request
    rv = self.handle_user_exception(e)
  File "D:\Anaconda3\envs\test_py3\lib\site-packages\flask\app.py", line 1718, in handle_user_exception
    reraise(exc_type, exc_value, tb)
  File "D:\Anaconda3\envs\test_py3\lib\site-packages\flask\_compat.py", line 35, in reraise
    raise value
  File "D:\Anaconda3\envs\test_py3\lib\site-packages\flask\app.py", line 1813, in full_dispatch_request
    rv = self.dispatch_request()
  File "D:\Anaconda3\envs\test_py3\lib\site-packages\flask\app.py", line 1799, in dispatch_request
    return self.view_functions[rule.endpoint](**req.view_args)
  File "E:\github\mycode\recruitment\app\main\user\views.py", line 21, in add
    form = AddUserForm()
  File "D:\Anaconda3\envs\test_py3\lib\site-packages\wtforms\form.py", line 212, in __call__
    return type.__call__(cls, *args, **kwargs)
TypeError: __init__() missing 1 required positional argument: 'user'
2018-11-07 16:03:13,587 ERROR: Exception on /user/add [GET] [in D:\Anaconda3\envs\test_py3\lib\site-packages\flask\app.py:1761]
Traceback (most recent call last):
  File "D:\Anaconda3\envs\test_py3\lib\site-packages\flask\app.py", line 2292, in wsgi_app
    response = self.full_dispatch_request()
  File "D:\Anaconda3\envs\test_py3\lib\site-packages\flask\app.py", line 1815, in full_dispatch_request
    rv = self.handle_user_exception(e)
  File "D:\Anaconda3\envs\test_py3\lib\site-packages\flask\app.py", line 1718, in handle_user_exception
    reraise(exc_type, exc_value, tb)
  File "D:\Anaconda3\envs\test_py3\lib\site-packages\flask\_compat.py", line 35, in reraise
    raise value
  File "D:\Anaconda3\envs\test_py3\lib\site-packages\flask\app.py", line 1813, in full_dispatch_request
    rv = self.dispatch_request()
  File "D:\Anaconda3\envs\test_py3\lib\site-packages\flask\app.py", line 1799, in dispatch_request
    return self.view_functions[rule.endpoint](**req.view_args)
  File "E:\github\mycode\recruitment\app\main\user\views.py", line 21, in add
    form = AddUserForm()
  File "D:\Anaconda3\envs\test_py3\lib\site-packages\wtforms\form.py", line 212, in __call__
    return type.__call__(cls, *args, **kwargs)
TypeError: __init__() missing 1 required positional argument: 'user'
2018-11-07 16:03:14,854 ERROR: Exception on /user/add [GET] [in D:\Anaconda3\envs\test_py3\lib\site-packages\flask\app.py:1761]
Traceback (most recent call last):
  File "D:\Anaconda3\envs\test_py3\lib\site-packages\flask\app.py", line 2292, in wsgi_app
    response = self.full_dispatch_request()
  File "D:\Anaconda3\envs\test_py3\lib\site-packages\flask\app.py", line 1815, in full_dispatch_request
    rv = self.handle_user_exception(e)
  File "D:\Anaconda3\envs\test_py3\lib\site-packages\flask\app.py", line 1718, in handle_user_exception
    reraise(exc_type, exc_value, tb)
  File "D:\Anaconda3\envs\test_py3\lib\site-packages\flask\_compat.py", line 35, in reraise
    raise value
  File "D:\Anaconda3\envs\test_py3\lib\site-packages\flask\app.py", line 1813, in full_dispatch_request
    rv = self.dispatch_request()
  File "D:\Anaconda3\envs\test_py3\lib\site-packages\flask\app.py", line 1799, in dispatch_request
    return self.view_functions[rule.endpoint](**req.view_args)
  File "E:\github\mycode\recruitment\app\main\user\views.py", line 21, in add
    form = AddUserForm()
  File "D:\Anaconda3\envs\test_py3\lib\site-packages\wtforms\form.py", line 212, in __call__
    return type.__call__(cls, *args, **kwargs)
TypeError: __init__() missing 1 required positional argument: 'user'
2018-11-07 16:03:14,865 ERROR: Exception on /user/add [GET] [in D:\Anaconda3\envs\test_py3\lib\site-packages\flask\app.py:1761]
Traceback (most recent call last):
  File "D:\Anaconda3\envs\test_py3\lib\site-packages\flask\app.py", line 2292, in wsgi_app
    response = self.full_dispatch_request()
  File "D:\Anaconda3\envs\test_py3\lib\site-packages\flask\app.py", line 1815, in full_dispatch_request
    rv = self.handle_user_exception(e)
  File "D:\Anaconda3\envs\test_py3\lib\site-packages\flask\app.py", line 1718, in handle_user_exception
    reraise(exc_type, exc_value, tb)
  File "D:\Anaconda3\envs\test_py3\lib\site-packages\flask\_compat.py", line 35, in reraise
    raise value
  File "D:\Anaconda3\envs\test_py3\lib\site-packages\flask\app.py", line 1813, in full_dispatch_request
    rv = self.dispatch_request()
  File "D:\Anaconda3\envs\test_py3\lib\site-packages\flask\app.py", line 1799, in dispatch_request
    return self.view_functions[rule.endpoint](**req.view_args)
  File "E:\github\mycode\recruitment\app\main\user\views.py", line 21, in add
    form = AddUserForm()
  File "D:\Anaconda3\envs\test_py3\lib\site-packages\wtforms\form.py", line 212, in __call__
    return type.__call__(cls, *args, **kwargs)
TypeError: __init__() missing 1 required positional argument: 'user'
2018-11-07 16:03:20,052 ERROR: Exception on /user/add [GET] [in D:\Anaconda3\envs\test_py3\lib\site-packages\flask\app.py:1761]
Traceback (most recent call last):
  File "D:\Anaconda3\envs\test_py3\lib\site-packages\flask\app.py", line 2292, in wsgi_app
    response = self.full_dispatch_request()
  File "D:\Anaconda3\envs\test_py3\lib\site-packages\flask\app.py", line 1815, in full_dispatch_request
    rv = self.handle_user_exception(e)
  File "D:\Anaconda3\envs\test_py3\lib\site-packages\flask\app.py", line 1718, in handle_user_exception
    reraise(exc_type, exc_value, tb)
  File "D:\Anaconda3\envs\test_py3\lib\site-packages\flask\_compat.py", line 35, in reraise
    raise value
  File "D:\Anaconda3\envs\test_py3\lib\site-packages\flask\app.py", line 1813, in full_dispatch_request
    rv = self.dispatch_request()
  File "D:\Anaconda3\envs\test_py3\lib\site-packages\flask\app.py", line 1799, in dispatch_request
    return self.view_functions[rule.endpoint](**req.view_args)
  File "E:\github\mycode\recruitment\app\main\user\views.py", line 21, in add
    form = AddUserForm()
  File "D:\Anaconda3\envs\test_py3\lib\site-packages\wtforms\form.py", line 212, in __call__
    return type.__call__(cls, *args, **kwargs)
TypeError: __init__() missing 1 required positional argument: 'user'
2018-11-07 16:03:36,269 INFO: 公司后台 startup [in E:\github\mycode\recruitment\app\__init__.py:85]
2018-11-07 16:03:40,131 ERROR: Exception on /user/add [GET] [in D:\Anaconda3\envs\test_py3\lib\site-packages\flask\app.py:1761]
Traceback (most recent call last):
  File "D:\Anaconda3\envs\test_py3\lib\site-packages\flask\app.py", line 2292, in wsgi_app
    response = self.full_dispatch_request()
  File "D:\Anaconda3\envs\test_py3\lib\site-packages\flask\app.py", line 1815, in full_dispatch_request
    rv = self.handle_user_exception(e)
  File "D:\Anaconda3\envs\test_py3\lib\site-packages\flask\app.py", line 1718, in handle_user_exception
    reraise(exc_type, exc_value, tb)
  File "D:\Anaconda3\envs\test_py3\lib\site-packages\flask\_compat.py", line 35, in reraise
    raise value
  File "D:\Anaconda3\envs\test_py3\lib\site-packages\flask\app.py", line 1813, in full_dispatch_request
    rv = self.dispatch_request()
  File "D:\Anaconda3\envs\test_py3\lib\site-packages\flask\app.py", line 1799, in dispatch_request
    return self.view_functions[rule.endpoint](**req.view_args)
  File "E:\github\mycode\recruitment\app\main\user\views.py", line 21, in add
    form = AddUserForm()
  File "D:\Anaconda3\envs\test_py3\lib\site-packages\wtforms\form.py", line 212, in __call__
    return type.__call__(cls, *args, **kwargs)
TypeError: __init__() missing 1 required positional argument: 'user'
2018-11-07 16:03:40,216 ERROR: Exception on /user/add [GET] [in D:\Anaconda3\envs\test_py3\lib\site-packages\flask\app.py:1761]
Traceback (most recent call last):
  File "D:\Anaconda3\envs\test_py3\lib\site-packages\flask\app.py", line 2292, in wsgi_app
    response = self.full_dispatch_request()
  File "D:\Anaconda3\envs\test_py3\lib\site-packages\flask\app.py", line 1815, in full_dispatch_request
    rv = self.handle_user_exception(e)
  File "D:\Anaconda3\envs\test_py3\lib\site-packages\flask\app.py", line 1718, in handle_user_exception
    reraise(exc_type, exc_value, tb)
  File "D:\Anaconda3\envs\test_py3\lib\site-packages\flask\_compat.py", line 35, in reraise
    raise value
  File "D:\Anaconda3\envs\test_py3\lib\site-packages\flask\app.py", line 1813, in full_dispatch_request
    rv = self.dispatch_request()
  File "D:\Anaconda3\envs\test_py3\lib\site-packages\flask\app.py", line 1799, in dispatch_request
    return self.view_functions[rule.endpoint](**req.view_args)
  File "E:\github\mycode\recruitment\app\main\user\views.py", line 21, in add
    form = AddUserForm()
  File "D:\Anaconda3\envs\test_py3\lib\site-packages\wtforms\form.py", line 212, in __call__
    return type.__call__(cls, *args, **kwargs)
TypeError: __init__() missing 1 required positional argument: 'user'
