2018-11-07 17:27:50,875 ERROR: Exception on /user/add [GET] [in D:\Anaconda3\envs\test_py3\lib\site-packages\flask\app.py:1761]
Traceback (most recent call last):
  File "D:\Anaconda3\envs\test_py3\lib\site-packages\flask\app.py", line 2292, in wsgi_app
    response = self.full_dispatch_request()
  File "D:\Anaconda3\envs\test_py3\lib\site-packages\flask\app.py", line 1815, in full_dispatch_request
    rv = self.handle_user_exception(e)
  File "D:\Anaconda3\envs\test_py3\lib\site-packages\flask\app.py", line 1718, in handle_user_exception
    reraise(exc_type, exc_value, tb)
  File "D:\Anaconda3\envs\test_py3\lib\site-packages\flask\_compat.py", line 35, in reraise
    raise value
  File "D:\Anaconda3\envs\test_py3\lib\site-packages\flask\app.py", line 1813, in full_dispatch_request
    rv = self.dispatch_request()
  File "D:\Anaconda3\envs\test_py3\lib\site-packages\flask\app.py", line 1799, in dispatch_request
    return self.view_functions[rule.endpoint](**req.view_args)
  File "E:\github\mycode\recruitment\app\main\user\views.py", line 21, in add
    form = AddUserForm()
  File "D:\Anaconda3\envs\test_py3\lib\site-packages\wtforms\form.py", line 212, in __call__
    return type.__call__(cls, *args, **kwargs)
  File "E:\github\mycode\recruitment\app\main\user\forms.py", line 46, in __init__
    for dept in Dept.query.order_by(Dept.name).all()]
AttributeError: 'AddUserForm' object has no attribute 'dept'
2018-11-07 17:27:51,433 ERROR: Exception on /user/add [GET] [in D:\Anaconda3\envs\test_py3\lib\site-packages\flask\app.py:1761]
Traceback (most recent call last):
  File "D:\Anaconda3\envs\test_py3\lib\site-packages\flask\app.py", line 2292, in wsgi_app
    response = self.full_dispatch_request()
  File "D:\Anaconda3\envs\test_py3\lib\site-packages\flask\app.py", line 1815, in full_dispatch_request
    rv = self.handle_user_exception(e)
  File "D:\Anaconda3\envs\test_py3\lib\site-packages\flask\app.py", line 1718, in handle_user_exception
    reraise(exc_type, exc_value, tb)
  File "D:\Anaconda3\envs\test_py3\lib\site-packages\flask\_compat.py", line 35, in reraise
    raise value
  File "D:\Anaconda3\envs\test_py3\lib\site-packages\flask\app.py", line 1813, in full_dispatch_request
    rv = self.dispatch_request()
  File "D:\Anaconda3\envs\test_py3\lib\site-packages\flask\app.py", line 1799, in dispatch_request
    return self.view_functions[rule.endpoint](**req.view_args)
  File "E:\github\mycode\recruitment\app\main\user\views.py", line 21, in add
    form = AddUserForm()
  File "D:\Anaconda3\envs\test_py3\lib\site-packages\wtforms\form.py", line 212, in __call__
    return type.__call__(cls, *args, **kwargs)
  File "E:\github\mycode\recruitment\app\main\user\forms.py", line 46, in __init__
    for dept in Dept.query.order_by(Dept.name).all()]
AttributeError: 'AddUserForm' object has no attribute 'dept'
2018-11-07 17:27:56,526 ERROR: Exception on /user/add [GET] [in D:\Anaconda3\envs\test_py3\lib\site-packages\flask\app.py:1761]
Traceback (most recent call last):
  File "D:\Anaconda3\envs\test_py3\lib\site-packages\flask\app.py", line 2292, in wsgi_app
    response = self.full_dispatch_request()
  File "D:\Anaconda3\envs\test_py3\lib\site-packages\flask\app.py", line 1815, in full_dispatch_request
    rv = self.handle_user_exception(e)
  File "D:\Anaconda3\envs\test_py3\lib\site-packages\flask\app.py", line 1718, in handle_user_exception
    reraise(exc_type, exc_value, tb)
  File "D:\Anaconda3\envs\test_py3\lib\site-packages\flask\_compat.py", line 35, in reraise
    raise value
  File "D:\Anaconda3\envs\test_py3\lib\site-packages\flask\app.py", line 1813, in full_dispatch_request
    rv = self.dispatch_request()
  File "D:\Anaconda3\envs\test_py3\lib\site-packages\flask\app.py", line 1799, in dispatch_request
    return self.view_functions[rule.endpoint](**req.view_args)
  File "E:\github\mycode\recruitment\app\main\user\views.py", line 21, in add
    form = AddUserForm()
  File "D:\Anaconda3\envs\test_py3\lib\site-packages\wtforms\form.py", line 212, in __call__
    return type.__call__(cls, *args, **kwargs)
  File "E:\github\mycode\recruitment\app\main\user\forms.py", line 46, in __init__
    for dept in Dept.query.order_by(Dept.name).all()]
AttributeError: 'AddUserForm' object has no attribute 'dept'
2018-11-07 17:28:43,460 INFO: 公司后台 startup [in E:\github\mycode\recruitment\app\__init__.py:85]
2018-11-07 17:28:46,927 ERROR: Exception on /user/add [GET] [in D:\Anaconda3\envs\test_py3\lib\site-packages\flask\app.py:1761]
Traceback (most recent call last):
  File "D:\Anaconda3\envs\test_py3\lib\site-packages\flask\app.py", line 2292, in wsgi_app
    response = self.full_dispatch_request()
  File "D:\Anaconda3\envs\test_py3\lib\site-packages\flask\app.py", line 1815, in full_dispatch_request
    rv = self.handle_user_exception(e)
  File "D:\Anaconda3\envs\test_py3\lib\site-packages\flask\app.py", line 1718, in handle_user_exception
    reraise(exc_type, exc_value, tb)
  File "D:\Anaconda3\envs\test_py3\lib\site-packages\flask\_compat.py", line 35, in reraise
    raise value
  File "D:\Anaconda3\envs\test_py3\lib\site-packages\flask\app.py", line 1813, in full_dispatch_request
    rv = self.dispatch_request()
  File "D:\Anaconda3\envs\test_py3\lib\site-packages\flask\app.py", line 1799, in dispatch_request
    return self.view_functions[rule.endpoint](**req.view_args)
  File "E:\github\mycode\recruitment\app\main\user\views.py", line 22, in add
    form = AddUserForm()
  File "D:\Anaconda3\envs\test_py3\lib\site-packages\wtforms\form.py", line 212, in __call__
    return type.__call__(cls, *args, **kwargs)
  File "E:\github\mycode\recruitment\app\main\user\forms.py", line 46, in __init__
    for dept in Dept.query.order_by(Dept.name).all()]
AttributeError: 'AddUserForm' object has no attribute 'dept'
2018-11-07 17:28:47,016 ERROR: Exception on /user/add [GET] [in D:\Anaconda3\envs\test_py3\lib\site-packages\flask\app.py:1761]
Traceback (most recent call last):
  File "D:\Anaconda3\envs\test_py3\lib\site-packages\flask\app.py", line 2292, in wsgi_app
    response = self.full_dispatch_request()
  File "D:\Anaconda3\envs\test_py3\lib\site-packages\flask\app.py", line 1815, in full_dispatch_request
    rv = self.handle_user_exception(e)
  File "D:\Anaconda3\envs\test_py3\lib\site-packages\flask\app.py", line 1718, in handle_user_exception
    reraise(exc_type, exc_value, tb)
  File "D:\Anaconda3\envs\test_py3\lib\site-packages\flask\_compat.py", line 35, in reraise
    raise value
  File "D:\Anaconda3\envs\test_py3\lib\site-packages\flask\app.py", line 1813, in full_dispatch_request
    rv = self.dispatch_request()
  File "D:\Anaconda3\envs\test_py3\lib\site-packages\flask\app.py", line 1799, in dispatch_request
    return self.view_functions[rule.endpoint](**req.view_args)
  File "E:\github\mycode\recruitment\app\main\user\views.py", line 22, in add
    form = AddUserForm()
  File "D:\Anaconda3\envs\test_py3\lib\site-packages\wtforms\form.py", line 212, in __call__
    return type.__call__(cls, *args, **kwargs)
  File "E:\github\mycode\recruitment\app\main\user\forms.py", line 46, in __init__
    for dept in Dept.query.order_by(Dept.name).all()]
AttributeError: 'AddUserForm' object has no attribute 'dept'
2018-11-07 17:29:19,099 INFO: 公司后台 startup [in E:\github\mycode\recruitment\app\__init__.py:85]
2018-11-07 17:30:32,702 INFO: 公司后台 startup [in E:\github\mycode\recruitment\app\__init__.py:85]
2018-11-07 17:31:07,972 INFO: 公司后台 startup [in E:\github\mycode\recruitment\app\__init__.py:85]
2018-11-07 17:31:49,927 INFO: 公司后台 startup [in E:\github\mycode\recruitment\app\__init__.py:85]
2018-11-07 17:32:12,168 INFO: 公司后台 startup [in E:\github\mycode\recruitment\app\__init__.py:85]
2018-11-07 17:33:57,688 INFO: 公司后台 startup [in E:\github\mycode\recruitment\app\__init__.py:85]
2018-11-07 17:34:14,221 INFO: 公司后台 startup [in E:\github\mycode\recruitment\app\__init__.py:85]
2018-11-07 17:35:03,244 INFO: 公司后台 startup [in E:\github\mycode\recruitment\app\__init__.py:85]
